WRITING API THE BOTTOM UP WAY

1. Repo layer -> ORM or raw queries.

2. Service Layer -> BL: Business Logic.

3. Controllers -> call the service layer -> send response

4. route setup

5 validators

6 embed validators to the routes


### VVVVIII
his is called the error-handling middleware ‚Äî like your genericErrorHandler.

How do errors reach it?
There are two ways:

next(error) ‚Äî this is the official, Express way to forward an error to the error middleware.

throw error ‚Äî works too if you‚Äôre using async/await, because Express handles rejected promises using next(error) under the hood.

so for async functions do return next(,..............("Error")) #########


############ COMPLETE ERROR FLOW UNDERSTANDING ###########

Yes Devansh ‚Äî you're **exactly right**. Let's walk through your understanding step by step to make it **100% crystal clear**, using simple terms and visuals.

---

## ‚úÖ Scenario: Throwing an error in the Repository layer

You wrote this in your **repository**:

```ts
if (!hotelExists) {
   throw new NotFoundError("Hotel not found");
}
```

### What happens next?

---

## üîÅ Step-by-Step Flow:

### 1Ô∏è‚É£ **Repository Layer** (lowest layer)

* The function is `async`.
* When you `throw` inside it, it rejects the Promise:

```ts
throw new NotFoundError("Hotel not found");
```

üëâ This behaves the same as:

```ts
return Promise.reject(new NotFoundError(...));
```

---

### 2Ô∏è‚É£ **Service Layer** (middle layer)

You wrote:

```ts
export async function deleteHotelByIdService(id: number){
    const isDeleted = await deleteHotelById(id); // ‚Üê awaits repo layer
    return isDeleted;
}
```

* Since `deleteHotelById(id)` throws an error, that means:

```ts
await deleteHotelById(id);
```

* This line causes an **unhandled rejection**, so the \`error travels up to the caller\*\*, i.e., the controller.

üß† Important: You didn't handle the error here with try/catch ‚Äî so it **bubbles up to the controller**.

---

### 3Ô∏è‚É£ **Controller Layer** (top layer)

You wrote:

```ts
try {
   const isDeleted = await deleteHotelByIdService(id);
} catch (error) {
   if (error instanceof NotFoundError) throw error;
   throw new InternalServerError(...);
}
```

* Now the `catch` block catches the error thrown from the repo layer.
* You either:

  * **re-throw it** (to be handled by global error middleware), or
  * **transform it** to another error type.

---

### 4Ô∏è‚É£ **Error Middleware**

Since Express sees that an error was thrown or passed via `next(error)`, it finally invokes:

```ts
app.use(genericErrorHandler); // your global handler

function genericErrorHandler(err, req, res, next) {
   res.status(err.statusCode).json({ success: false, message: err.message });
}
```

---

## ‚úÖ Summary: What You Said ‚Äî Explained in Simple Terms

> ‚ùì ‚ÄúIf I throw any error in the repo layer ‚Üí it goes to the service layer where no error handling is done ‚Üí so the error reaches the controller layer where I call the service using `await` ‚Äî is this correct?‚Äù

**‚úÖ YES. 100% correct.**

### In Short:

| Layer         | What Happens                                                                            |
| ------------- | --------------------------------------------------------------------------------------- |
| Repository    | `throw error` ‚Üí rejects the async function                                              |
| Service       | `await repo()` ‚Üí Promise rejected, no catch, so error moves on                          |
| Controller    | `await service()` ‚Üí Promise rejected ‚Üí caught in try/catch block                        |
| Error Handler | If controller throws or calls `next(error)`, Express routes it to `genericErrorHandler` |

---

Let me know if you want a **visual flowchart** of this process ‚Äî I can create one to help cement the concept.
